Workbook

Sheet Instrucciones
B2: Herramienta de Monitoreo y Evaluación Cadenas de Valor Inclusivas | CI2: Con software nos referimos a cualquier programa o sistema operativo que apoye al negocio en la gestión de sus operaciones. Desde MS Microsoft hasta softwares de gestión (SAP, Oracle)
B4: La siguiente herramienta es una de las más importantes para monitorear y evaluar el desempeño y resultados de los negocios participantes del Programa de Cadenas de Valor Inclusivas del PNUD. Cada pregunta ha sido formulada para sumar a los indicadores de medición de efectividad del Programa, además de identificar oportunidades y prioridades en las implementaciones específicas.
B7: Instrucciones:
A8: 1. | B8: Las preguntas están divididas en 10 categorías: Implementación, Información General del Decisor (a) del negocio, Gestión General del Negocio, Generación de Empleo, Operaciones y Ventas, Gestión Financiera, Cultura Organizacional, Gestión del Riesgo de Desastres, y Gestión Ambiental.
A9: 2. | B9: La herramienta está construida para contemplar tanto la información al inicio de la implementación (captura inicial) como la información de cierre (captura final). Algunas categorías solo serán llenadas una vez (Implementación o Información General del Decisor (a)). Las respuestas de la captura final, solo deberán ser llenadas al final de la implementación para comparar los resultados de inicio. Están marcados en color azul y con la palabra "FINAL".
A10: 3. | B10: Cada fila de llenado representa a un negocio. El 98% de los campos son obligatorios. (solo hay dos pregunta que dependen)
A11: 4. | B11: Se deberá elegir la respuesta más adecuada o que mejor responda la situación del negocio al momento de aplicar la herramienta
A12: 5. | B12: Antes de iniciar el llenado, copiar las filas necesarias para llenar los datos de cada una de los negocios asignados
A13: 6. | B13: Alguanas preguntas cuentan con una breve explicación en la Fila 2. Aún así, en caso no tener claridad, contactar al equipo del PNUD para mayor explicación.
A14: 7. | B14: Se recomienda que una sola persona llene el documento para evitar errores. Es esencial que se comparta la información recabada con el negocio. No olvide guardar los cambios ejecutados en el documento antes de cerrarlo.
A15: 8. | B15: La pestaña del DASHBOARD, no debe ser modificada, únicamente deberá utilizarse para utilizarse para el análisis de los datos
B19: Queda prohibida la reproducción de esta herramienta o uso externo fuera de la implementación del Programa de Cadenas de Valor Inclusivas del Programa de las Naciones Unidas para el Desarrollo.

Sheet M&E_ESP_FINAL
B2: Herramienta de Monitoreo y Evaluación Cadenas de Valor Inclusivas | E2: El decisor(a) del negocio es aquella persona responsible de la toma de decisión final de la organización. Algunas veces es el dueño(a) del negocio, otras veces el Gerente General, etc. | G2: Omitir pregunta en caso se aplique en SDP | W2: Omitir en caso la respuesta sea no | AH2: Las discapacidades pueden ser clasificadas en físicas, visual/auditiva, intelectual, psicosocial, múltiple. Esta pregunta no necesita especificación del tipo de discapacidad. | AJ2: Una persona en situación de vulnerabilidad es aquella que sufre múltiples desventajas estructurales (económicas, sociales, de salud, de género, étnicas, territoriales, etc) | AP2: Puede especificarse en moneda local | AQ2: Puede especificarse en moneda local | AR2: Es importante que si no se cuenta con este dato, debe apoyarse a calcularlo y agregarlo. El margen de utilidad bruta es un indicador financiero que muestra qué tan rentable es la negocio antes de considerar gastos operativos, impuestos y otros costos indirectos. Se calcula a partir de las ventas y el costo directo de producir los bienes o servicios. | AT2: El total de horas trabajadas es la sumatoria total de todas las horas trabajadas por todos los(as) empleados del negocio en un determinado periodo | AV2: Esta pregunta es importante porque nos permite conocer el volumen de productos fabricados o servicios entregados por su negocio. Con esta información podemos calcular indicadores clave como la productividad y la innovación en productos, que son fundamentales para evaluar el desempeño y el crecimiento del negocio. | BB2: Incluya únicamente negocios u organizaciones registradas fiscalmente que compran directamente sus productos o servicios, no distribuidores ni consumidores finales. | BD2: Colocar el número | BE2: Colocar el número | CJ2: Con software nos referimos a cualquier programa o sistema operativo que apoye al negocio en la gestión de sus operaciones. Desde MS Microsoft hasta softwares de gestión (SAP, Oracle)
B3: Implementación | D3: Información General del decisor (a) del negocio | H3: Información General del Negocio | Z3: Generación de empleo | AN3: Operaciones y ventas | BN3: Gestión Financiera | BX3: Cultura organizacional | CH3: Digitalización | CN3: Gestión del Riesgo de desastres | CT3: Gestión ambiental
Q4: INICIO | R4: FINAL | S4: INICIO | T4: FINAL | U4: INICIO | V4: FINAL | W4: INICIO | X4: FINAL | Y4: INICIO | Z4: INICIO | AA4: FINAL | AB4: INICIO | AC4: FINAL | AD4: INICIO | AE4: FINAL | AF4: INICIO | AG4: FINAL | AH4: INICIO | AI4: FINAL | AJ4: INICIO | AK4: FINAL | AL4: INICIO | AM4: FINAL | AN4: INICIO | AO4: FINAL | AP4: INICIO | AQ4: FINAL | AR4: INICIO | AS4: FINAL | AT4: INICIO | AU4: FINAL | AV4: INICIO | AW4: FINAL | AX4: INICIO | AY4: FINAL | AZ4: INICIO | BA4: FINAL | BB4: INICIO | BC4: FINAL | BD4: INICIO | BE4: FINAL | BF4: INICIO | BG4: FINAL | BH4: INICIO | BI4: FINAL | BJ4: INICIO | BK4: FINAL | BL4: INICIO | BM4: FINAL | BN4: INICIO | BO4: FINAL | BP4: INICIO | BQ4: FINAL | BR4: INICIO | BS4: FINAL | BT4: INICIO | BU4: FINAL | BV4: INICIO | BW4: FINAL | BX4: INICIO | BY4: FINAL | BZ4: INICIO | CA4: FINAL | CB4: INICIO | CC4: FINAL | CD4: INICIO | CE4: FINAL | CF4: INICIO | CG4: FINAL | CH4: INICIO | CI4: FINAL | CJ4: INICIO | CK4: FINAL | CL4: INICIO | CM4: FINAL | CN4: INICIO | CO4: FINAL | CP4: INICIO | CQ4: FINAL | CR4: INICIO | CS4: FINAL | CT4: INICIO | CU4: FINAL | CV4: INICIO | CW4: FINAL
B5: País | C5: Metodología aplicada | D5: Género | E5: Edad | F5: Nivel educativo | G5: ¿Es el negocio su principal fuente de ingresos? | H5: Nombre comercial del negocio | I5: Tipo de propiedad de su negocio | J5: Municipio | K5: Región | L5: Describir la actividad económica específica del negocio | M5: CIIU un dígito | N5: CIIU a dos dígitos | O5: CIIU a tres dígitos | P5: Años en operación (periodo de tiempo en el que el negocio opera activamente y puede ser distinto a años desde la fundación) | Q5: ¿Su negocio cuenta con registro legal activo? | R5: ¿Su negocio cuenta con registro legal activo? | S5: ¿Su negocio cumple con las obligaciones tributarias correspondientes? | T5: ¿Su negocio cumple con las obligaciones tributarias correspondientes? | U5: ¿Su negocio participa en redes, plataformas o espacios que fomenten alianzas estratégicas y colaboración con otras organizaciones? | V5: ¿Su negocio participa en redes, plataformas o espacios que fomenten alianzas estratégicas y colaboración con otras organizaciones? | W5: Si la respuesta es sí, especifique cuáles. Opción múltiple | X5: Si la respuesta es sí, especifique cuáles. Opción múltiple | Y5: ¿Usted o alguien de su equipo ha recibido capacitación formal relacionada con la gestión y operación del negocio? (Por ejemplo: cursos, talleres, diplomados en administración, finanzas, marketing, etc.) | Z5: ¿Cuántas personas en total trabajan actualmente en su negocio? Si es un negocio unipersonal, incluir a la persona dueña. También incluir personal temporal y fijo. | AA5: ¿Cuántas personas en total trabajan actualmente en su negocio? Si es un negocio unipersonal, incluir a la persona dueña. También incluir personal temporal y fijo. | AB5: ¿A cuántas mujeres emplea actualmente su negocio? No incluir a la persona dueña. Sí incluya personal temporal y fijo. | AC5: ¿A cuántas mujeres emplea actualmente su negocio? No incluir a la persona dueña. Sí incluya personal temporal y fijo. | AD5: ¿A cuántos hombres emplea actualmente su negocio? No incluir a la persona dueña. Sí incluya personal temporal y fijo. | AE5: ¿A cuántos hombres emplea actualmente su negocio? No incluir a la persona dueña. Sí incluya personal temporal y fijo. | AF5: ¿A cuántos jóvenes (mujeres y hombres) emplea actualmente su negocio? No incluir a la persona dueña. Sí incluya personal temporal y fijo. Una persona joven se considera entre los 18 a los 29 años. | AG5: ¿A cuántos jóvenes (mujeres y hombres) emplea actualmente su negocio? No incluir a la persona dueña. Sí incluya personal temporal y fijo. Una persona joven se considera entre los 18 a los 29 años. | AH5: ¿Cuántas personas con alguna discapacidad emplea actualmente su negocio? No incluir a la persona dueña. Sí incluya personal temporal y fijo. | AI5: ¿Cuántas personas con alguna discapacidad emplea actualmente su negocio? No incluir a la persona dueña. Sí incluya personal temporal y fijo. | AJ5: ¿Cuántas personas en situación de vulnerabilidad emplea actualmente su negocio? No incluir a la persona dueña. Sí incluya personal temporal y fijo. | AK5: ¿Cuántas personas en situación de vulnerabilidad emplea actualmente su negocio? No incluir a la persona dueña. Sí incluya personal temporal y fijo. | AL5: ¿Cuenta con un proceso de selección de personal que asegure la inclusión y la no discriminación? | AM5: ¿Cuenta con un proceso de selección de personal que asegure la inclusión y la no discriminación? | AN5: ¿Su negocio lleva un registro ordenado y constante de sus ventas y costos? (Esto incluye anotar todas las ventas y los costos asociados de manera regular, para poder calcular indicadores como el margen bruto). | AO5: ¿Su negocio lleva un registro ordenado y constante de sus ventas y costos? (Esto incluye anotar todas las ventas y los costos asociados de manera regular, para poder calcular indicadores como el margen bruto). | AP5: ¿Cuál es el promedio mensual de ventas de su negocio en CUP? (Si su negocio es estacional, calcule el promedio dividiendo el total de ventas del último año calendario entre 12 meses). | AQ5: ¿Cuál es el promedio mensual de ventas de su negocio en CUP? (Si su negocio es estacional, calcule el promedio dividiendo el total de ventas del último año calendario entre 12 meses). | AR5: ¿Cuál es el margen (%) de utilidad bruta de su negocio? | AS5: ¿Cuál es el margen (%) de utilidad bruta de su negocio? | AT5: ¿Cuál es el total de horas trabajadas en un mes aproximadamente? | AU5: ¿Cuál es el total de horas trabajadas en un mes aproximadamente? | AV5: ¿Cuántos productos fabrica o cuántos servicios entrega su negocio en promedio al mes? (Indique un número aproximado considerando la producción o prestación habitual. Si su negocio es estacional, calcule el promedio mensual tomando el total anual y dividiéndolo entre 12). | AW5: ¿Cuántos productos fabrica o cuántos servicios entrega su negocio en promedio al mes? (Indique un número aproximado considerando la producción o prestación habitual. Si su negocio es estacional, calcule el promedio mensual tomando el total anual y dividiéndolo entre 12). | AX5: En los últimos 3 meses, ¿su negocio ha introducido nuevos productos o servicios, o ha innovado en los existentes (por ejemplo, mejoras en diseño, funcionalidad o procesos)? | AY5: En los últimos 3 meses, ¿su negocio ha introducido nuevos productos o servicios, o ha innovado en los existentes (por ejemplo, mejoras en diseño, funcionalidad o procesos)? | AZ5: ¿En promedio, cuántos clientes finales (personas) atiende su negocio al mes? (Si su negocio es estacional, calcule el promedio mensual tomando el total de clientes atendidos en el último año y divídalo entre 12). | BA5: ¿En promedio, cuántos clientes finales (personas) atiende su negocio al mes? (Si su negocio es estacional, calcule el promedio mensual tomando el total de clientes atendidos en el último año y divídalo entre 12). | BB5: ¿En promedio, cuántos clientes comerciales (negocios u otras entidades registradas fiscalmente) atiende su negocio al mes? (Si su negocio es estacional, calcule el promedio mensual tomando el total de clientes comerciales atendidos en el último año y divídalo entre 12). | BC5: ¿En promedio, cuántos clientes comerciales (negocios u otras entidades registradas fiscalmente) atiende su negocio al mes? (Si su negocio es estacional, calcule el promedio mensual tomando el total de clientes comerciales atendidos en el último año y divídalo entre 12). | BD5: ¿Cuántos canales de venta tiene el negocio? Colocar el número | BE5: ¿Cuántos canales de venta tiene el negocio? | BF5: ¿Cuáles son los principales canales de venta de su negocio? Selección múltiple | BG5: ¿Cuáles son los principales canales de venta de su negocio? Selección múltiple | BH5: ¿Qué tan competitiva considera que es su negocio? | BI5: ¿Qué tan competitiva considera que es su negocio? | BJ5: ¿Su negocio segmenta el mercado por criterios demográficos, psicográficos o de género? | BK5: ¿Su negocio segmenta el mercado por criterios demográficos, psicográficos o de género? | BL5: ¿Su negocio dispone de elementos de imagen comercial, como logotipo, colores corporativos y diseño consistente en sus materiales? | BM5: ¿Su negocio dispone de elementos de imagen comercial, como logotipo, colores corporativos y diseño consistente en sus materiales? | BN5: ¿Cómo describiría el nivel de gestión financiera? | BO5: ¿Cómo describiría el nivel de gestión financiera? | BP5: ¿El negocio separa satisfactoriamente las finanzas personales de las finanzas del negocio? | BQ5: ¿El negocio separa satisfactoriamente las finanzas personales de las finanzas del negocio? | BR5: ¿Ha recibido capacitación en educación financiera en los últimos 12 meses? | BS5: ¿Ha recibido capacitación en educación financiera en los últimos 12 meses? | BT5: ¿Su negocio utiliza una cuenta bancaria propia para sus operaciones? | BU5: ¿Su negocio utiliza una cuenta bancaria propia para sus operaciones? | BV5: ¿Qué tipo(s) de financiamiento externo ha utilizado su negocio en los últimos 24 meses? | BW5: ¿Qué tipo(s) de financiamiento externo ha utilizado su negocio en los últimos 24 meses? | BX5: ¿Su negocio cuenta con prácticas y/o políticas que prohíben expresamente la violencia basada en género (VBG)? | BY5: ¿Su negocio cuenta con prácticas y/o políticas que prohíben expresamente la violencia basada en género (VBG)? | BZ5: ¿Su negocio ha definido explícitamente su modelo de negocio (por ejemplo, propuesta de valor, segmentos de clientes, canales, fuentes de ingresos, costos, etc.)? | CA5: ¿Su negocio ha definido explícitamente su modelo de negocio (por ejemplo, propuesta de valor, segmentos de clientes, canales, fuentes de ingresos, costos, etc.)? | CB5: ¿Su negocio establece objetivos y estrategias anuales/procesos de planificación estratégica para orientar sus actividades? | CC5: ¿Su negocio establece objetivos y estrategias anuales/procesos de planificación estratégica para orientar sus actividades? | CD5: ¿Su negocio promueve la igualdad en la remuneración? | CE5: ¿Su negocio promueve la igualdad en la remuneración? | CF5: ¿Qué nivel de participación tienen las mujeres de su negocio en espacios de toma de decisión? | CG5: ¿Qué nivel de participación tienen las mujeres de su negocio en espacios de toma de decisión? | CH5: ¿Qué presencia digital tiene su negocio (sitio web, redes sociales, e-commerce)? Seleccione principales plataformas. | CI5: ¿Qué presencia digital tiene su negocio (sitio web, redes sociales, e-commerce)? Seleccione principales plataformas. | CJ5: ¿Utiliza algún software para la operación del negocio? | CK5: ¿Utiliza algún software para la operación del negocio? | CL5: ¿Con qué frecuencia utiliza el negocio medios de pagos digitales? | CM5: ¿Con qué frecuencia utiliza el negocio medios de pagos digitales? | CN5: ¿El negocio ha identificado los principales riesgos que enfrenta? | CO5: ¿El negocio ha identificado los principales riesgos que enfrenta? | CP5: ¿Qué porcentaje de empleados está capacitado en gestión del riesgo de desastres? | CQ5: ¿Qué porcentaje de empleados está capacitado en gestión del riesgo de desastres? | CR5: ¿Existe un plan de continuidad de negocio documentado y actualizado? | CS5: ¿Existe un plan de continuidad de negocio documentado y actualizado? | CT5: ¿Su negocio cuenta con prácticas para la gestión adecuada de residuos sólidos generados por sus operaciones? (Por ejemplo: separación, reciclaje, disposición segura, recolección por gestores autorizados). | CU5: ¿Su negocio cuenta con prácticas para la gestión adecuada de residuos sólidos generados por sus operaciones? (Por ejemplo: separación, reciclaje, disposición segura, recolección por gestores autorizados). | CV5: ¿Mantiene un control del consumo de agua y energía de su negocio? | CW5: ¿Mantiene un control del consumo de agua y energía de su negocio?

Sheet DASHBOARD
C2: DASHBOARD M&E | L2: 0. Metodología aplicada
L3: CCSN | O3: =COUNTIF('M&E_ESP_FINAL'!$C$6:$C60,"CCSN") -> 0 | P3: =$O$3/$O$8 -> #DIV/0!
C4: Dashboard diseñador para resumir los resultados de la herramienta de Monitoreo y Evaluación del Programa de Cadenas de Valor Inclusivas | L4: ICSN | O4: =COUNTIF('M&E_ESP_FINAL'!$C$6:$C61,"ICSN") -> 0 | P4: =$O$4/$O$8 -> #DIV/0!
L5: MDP | O5: =COUNTIF('M&E_ESP_FINAL'!$C$6:$C62,"MDP") -> 0 | P5: =$O$5/$O$8 -> #DIV/0!
C6: POR FAVOR NO MODIFICAR | L6: En Marcha | O6: =COUNTIF('M&E_ESP_FINAL'!$C$6:$C63,"En Marcha") -> 0 | P6: =$O$6/$O$8 -> #DIV/0!
L7: En Marcha Digital | O7: =COUNTIF('M&E_ESP_FINAL'!$C$6:$C64,"En Marcha Digital") -> 0 | P7: =$O$7/$O$8 -> #DIV/0!
O8: =SUM(O3:O7) -> 0
B10: I. Información General del Decisor (a) del Negocio | N10: III. Generación de Empleo | Z10: VI. Cultura Organizacional
B12: 1. Género | E12: % | N12: 12. ¿Cuántas personas en total trabajan actualmente en su negocio? Incluir a la persona dueña y personal temporal y fijo. | Z12: 37. ¿Su negocio cuenta con prácticas y/o políticas que prohíben expresamente la violencia basada en género (VBG)?
B13: Mujer | D13: =COUNTIF('M&E_ESP_FINAL'!$D$6:$D60,"Mujer") -> 0 | E13: =$D$13/$D$17 -> #DIV/0! | O13: INICIO | Q13: FINAL
B14: Hombre | D14: =COUNTIF('M&E_ESP_FINAL'!$D$6:$D61,"Hombre") -> 0 | E14: =$D$14/$D$17 -> #DIV/0! | O14: =MEDIAN('M&E_ESP_FINAL'!$Z$6:$Z60) -> #NUM! | Q14: =MEDIAN('M&E_ESP_FINAL'!$AA$6:$AA60) -> #NUM! | AA14: INICIO | AC14: FINAL
B15: No Binaria | D15: =COUNTIF('M&E_ESP_FINAL'!$D$6:$D62,"No Binaria") -> 0 | E15: =$D$15/$D$17 -> #DIV/0! | Z15: No existen políticas | AA15: =COUNTIF('M&E_ESP_FINAL'!$BX$6:$BX60,"*No existen políticas*") -> 0 | AB15: =AA15/$AA$20 -> #DIV/0! | AC15: =COUNTIF('M&E_ESP_FINAL'!$BY$6:$BY60,"*No existen políticas*") -> 0 | AD15: =AC15/$AC$20 -> #DIV/0!
B16: Prefiero no especificar | D16: =COUNTIF('M&E_ESP_FINAL'!$D$6:$D63,"Prefiero no especificar") -> 0 | E16: =$D$16/$D$17 -> #DIV/0! | Z16: Hay prácticas informales | AA16: =COUNTIF('M&E_ESP_FINAL'!$BX$6:$BX60,"*Hay prácticas informales*") -> 0 | AB16: =AA16/$AA$20 -> #DIV/0! | AC16: =COUNTIF('M&E_ESP_FINAL'!$BY$6:$BY60,"*Hay prácticas informales*") -> 0 | AD16: =AC16/$AC$20 -> #DIV/0!
D17: =SUM($D$13:$D$16) -> 0 | N17: 13. ¿A cuántas mujeres emplea actualmente su negocio? No incluir a la persona dueña. Sí incluya personal temporal y fijo. | Z17: Existe al menos un documento | AA17: =COUNTIF('M&E_ESP_FINAL'!$BX$6:$BX60,"*Existe al menos un documento*") -> 0 | AB17: =AA17/$AA$20 -> #DIV/0! | AC17: =COUNTIF('M&E_ESP_FINAL'!$BY$6:$BY60,"*Existe al menos un documento*") -> 0 | AD17: =AC17/$AC$20 -> #DIV/0!
O18: INICIO | Q18: FINAL | Z18: La política está implementada | AA18: =COUNTIF('M&E_ESP_FINAL'!$BX$6:$BX60,"*La política está implementada*") -> 0 | AB18: =AA18/$AA$20 -> #DIV/0! | AC18: =COUNTIF('M&E_ESP_FINAL'!$BY$6:$BY60,"*La política está implementada*") -> 0 | AD18: =AC18/$AC$20 -> #DIV/0!
B19: 2. Edad Promedio | D19: =AVERAGE('M&E_ESP_FINAL'!$E$6:$E300) -> #DIV/0! | O19: =MEDIAN('M&E_ESP_FINAL'!$AB$6:$AB60) -> #NUM! | P19: =$O$19/$O$14 -> #NUM! | Q19: =MEDIAN('M&E_ESP_FINAL'!$AC$6:$AC60) -> #NUM! | R19: =$Q$19/$Q$14 -> #NUM! | Z19: La política está implementada, el personal está capacitado | AA19: =COUNTIF('M&E_ESP_FINAL'!$BX$6:$BX60,"*La política está implementada, el personal está capacitado*") -> 0 | AB19: =AA19/$AA$20 -> #DIV/0! | AC19: =COUNTIF('M&E_ESP_FINAL'!$BY$6:$BY60,"*La política está implementada, el personal está capacitado*") -> 0 | AD19: =AC19/$AC$20 -> #DIV/0!
AA20: =SUM(AA15:AA19) -> 0 | AC20: =SUM(AC15:AC19) -> 0
B21: Nivel Educativo | E21: %
B22: Básica | D22: =COUNTIF('M&E_ESP_FINAL'!$F$6:$F60,"Básica") -> 0 | E22: =$D22/$D$28 -> #DIV/0! | N22: 14. ¿A cuántos hombres emplea actualmente su negocio? No incluir a la persona dueña. Sí incluya personal temporal y fijo. | Z22: 38. ¿Su negocio ha definido explícitamente su modelo de negocio (por ejemplo, propuesta de valor, segmentos de clientes, canales, fuentes de ingresos, costos, etc.)?
B23: Ténica | D23: =COUNTIF('M&E_ESP_FINAL'!$F$6:$F61,"Técnica") -> 0 | E23: =$D23/$D$28 -> #DIV/0! | O23: INICIO | Q23: FINAL
B24: Universidad | D24: =COUNTIF('M&E_ESP_FINAL'!$F$6:$F62,"Universidad") -> 0 | E24: =$D24/$D$28 -> #DIV/0! | O24: =MEDIAN('M&E_ESP_FINAL'!$AD$6:$AD65) -> #NUM! | P24: =$O$24/$O$14 -> #NUM! | Q24: =MEDIAN('M&E_ESP_FINAL'!$AE$6:$AE65) -> #NUM! | R24: =$Q$24/$Q$14 -> #NUM! | AA24: INICIO | AC24: FINAL
B25: Posgrado | D25: =COUNTIF('M&E_ESP_FINAL'!$F$6:$F63,"Posgrado") -> 0 | E25: =$D25/$D$28 -> #DIV/0! | Z25: No tenemos un modelo de negocio definido. | AA25: =COUNTIF('M&E_ESP_FINAL'!$BZ$6:$BZ60,"*No tenemos un modelo de negocio definido*") -> 0 | AB25: =AA25/$AA$30 -> #DIV/0! | AC25: =COUNTIF('M&E_ESP_FINAL'!$CA$6:$CA60,"*No tenemos un modelo de negocio definido*") -> 0 | AD25: =AC25/$AC$30 -> #DIV/0!
B26: Sin instrucción formal | D26: =COUNTIF('M&E_ESP_FINAL'!$F$6:$F64,"Sin instrucción formal") -> 0 | E26: =$D26/$D$28 -> #DIV/0! | Z26: Conocemos algunos elementos | AA26: =COUNTIF('M&E_ESP_FINAL'!$BZ$6:$BZ60,"*Conocemos algunos elementos*") -> 0 | AB26: =AA26/$AA$30 -> #DIV/0! | AC26: =COUNTIF('M&E_ESP_FINAL'!$CA$6:$CA60,"*Conocemos algunos elementos*") -> 0 | AD26: =AC26/$AC$30 -> #DIV/0!
B27: Prefiere no especificar | D27: =COUNTIF('M&E_ESP_FINAL'!$F$6:$F65,"Prefiere no especificar") -> 0 | E27: =$D27/$D$28 -> #DIV/0! | N27: 15. ¿A cuántos jóvenes (mujeres y hombres) emplea actualmente su negocio? | Z27: Contamos con la mayoría de los elementos definidos, aunque sin documentación formal. | AA27: =COUNTIF('M&E_ESP_FINAL'!$BZ$6:$BZ60,"*Contamos con la mayoría de los elementos definidos, aunque sin documentación formal*") -> 0 | AB27: =AA27/$AA$30 -> #DIV/0! | AC27: =COUNTIF('M&E_ESP_FINAL'!$CA$6:$CA60,"*Contamos con la mayoría de los elementos definidos, aunque sin documentación formal*") -> 0 | AD27: =AC27/$AC$30 -> #DIV/0!
D28: =SUM($D$22:$D$27) -> 0 | O28: INICIO | Q28: FINAL | Z28: Tenemos un modelo de negocio completo | AA28: =COUNTIF('M&E_ESP_FINAL'!$BZ$6:$BZ60,"*Tenemos un modelo de negocio completo*") -> 0 | AB28: =AA28/$AA$30 -> #DIV/0! | AC28: =COUNTIF('M&E_ESP_FINAL'!$CA$6:$CA60,"*Tenemos un modelo de negocio completo*") -> 0 | AD28: =AC28/$AC$30 -> #DIV/0!
B29: 3. ¿Es el negocio su principal fuente de ingresos? | O29: =MEDIAN('M&E_ESP_FINAL'!$AF$6:$AF70) -> #NUM! | P29: =$O$29/$O$14 -> #NUM! | Q29: =MEDIAN('M&E_ESP_FINAL'!$AG$6:$AG70) -> #NUM! | R29: =$Q$29/$Q$14 -> #NUM! | Z29: El modelo de negocio está documentado | AA29: =COUNTIF('M&E_ESP_FINAL'!$BZ$6:$BZ60,"*El modelo de negocio está documentado*") -> 0 | AB29: =AA29/$AA$30 -> #DIV/0! | AC29: =COUNTIF('M&E_ESP_FINAL'!$CA$6:$CA60,"*El modelo de negocio está documentado*") -> 0 | AD29: =AC29/$AC$30 -> #DIV/0!
B30: Sí | D30: =COUNTIF('M&E_ESP_FINAL'!$G$6:$G60,"Sí") -> 0 | E30: =D30/$D$32 -> #DIV/0! | AA30: =SUM(AA25:AA29) -> 0 | AC30: =SUM(AC25:AC29) -> 0
B31: No | D31: =COUNTIF('M&E_ESP_FINAL'!$G$6:$G60,"No") -> 0 | E31: =D31/$D$32 -> #DIV/0!
D32: =SUM(D30:D31) -> 0 | N32: 16. ¿Cuántas personas con alguna discapacidad emplea actualmente su negocio? | Z32: 39. ¿Su negocio establece objetivos y estrategias anuales/procesos de planificación estratégica para orientar sus actividades?
B33: II. Información General del Negocio | O33: INICIO | Q33: FINAL
O34: =MEDIAN('M&E_ESP_FINAL'!$AH$6:$AH75) -> #NUM! | P34: =$O$34/$O$14 -> #NUM! | Q34: =MEDIAN('M&E_ESP_FINAL'!$AI$6:$AI75) -> #NUM! | R34: =$Q$34/$Q$14 -> #NUM! | AA34: INICIO | AC34: FINAL
B35: 4. Tipo de propiedad de su negocio | Z35: Sí, contamos con un plan | AA35: =COUNTIF('M&E_ESP_FINAL'!$CB$6:$CB60,"*Sí, contamos con un plan*") -> 0 | AB35: =AA35/$AA$39 -> #DIV/0! | AC35: =COUNTIF('M&E_ESP_FINAL'!$CC$6:$CC60,"*Sí, contamos con un plan*") -> 0 | AD35: =AC35/$AC$39 -> #DIV/0!
I36: % | Z36: Sí, definimos objetivos anuales | AA36: =COUNTIF('M&E_ESP_FINAL'!$CB$6:$CB60,"*Sí, definimos objetivos anuales*") -> 0 | AB36: =AA36/$AA$39 -> #DIV/0! | AC36: =COUNTIF('M&E_ESP_FINAL'!$CC$6:$CC60,"*Sí, definimos objetivos anuales*") -> 0 | AD36: =AC36/$AC$39 -> #DIV/0!
B37: Propietario único: Negocio propiedad de una sola persona, sin separación legal entre el dueño y la negocio. | H37: =COUNTIF('M&E_ESP_FINAL'!$I$6:$I60,"*Propietario único*") -> 0 | I37: =H37/$H$42 -> #DIV/0! | N37: 17. ¿Cuántas personas en situación de vulnerabilidad emplea actualmente su negocio? | Z37: Estamos en proceso de desarrollar objetivos | AA37: =COUNTIF('M&E_ESP_FINAL'!$CB$6:$CB60,"*Estamos en proceso de desarrollar objetivos*") -> 0 | AB37: =AA37/$AA$39 -> #DIV/0! | AC37: =COUNTIF('M&E_ESP_FINAL'!$CC$6:$CC60,"*Estamos en proceso de desarrollar objetivos*") -> 0 | AD37: =AC37/$AC$39 -> #DIV/0!
B38: Sociedad: Dos o más personas comparten propiedad y responsabilidad. | H38: =COUNTIF('M&E_ESP_FINAL'!$I$6:$I60,"*Sociedad*") -> 0 | I38: =H38/$H$42 -> #DIV/0! | O38: INICIO | Q38: FINAL | Z38: No realizamos planificación | AA38: =COUNTIF('M&E_ESP_FINAL'!$CB$6:$CB60,"*No realizamos planificación*") -> 0 | AB38: =AA38/$AA$39 -> #DIV/0! | AC38: =COUNTIF('M&E_ESP_FINAL'!$CC$6:$CC60,"*No realizamos planificación*") -> 0 | AD38: =AC38/$AC$39 -> #DIV/0!
B39: Sociedad de responsabilidad limitada: Estructura híbrida que ofrece responsabilidad limitada a los propietarios. | H39: =COUNTIF('M&E_ESP_FINAL'!$I$6:$I60,"*Sociedad de responsabilidad limitada*") -> 0 | I39: =H39/$H$42 -> #DIV/0! | O39: =MEDIAN('M&E_ESP_FINAL'!$AJ$6:$AJ80) -> #NUM! | P39: =$O$39/$O$14 -> #NUM! | Q39: =MEDIAN('M&E_ESP_FINAL'!$AK$6:$AK80) -> #NUM! | R39: =$Q$39/$Q$14 -> #NUM! | AA39: =SUM(AA35:AA38) -> 0 | AC39: =SUM(AC35:AC38) -> 0
B40: Sociedad anónima: Entidad legal separada de sus propietarios, con acciones y posibilidad de cotizar en bolsa. | H40: =COUNTIF('M&E_ESP_FINAL'!$I$6:$I60,"*Sociedad anónima*") -> 0 | I40: =H40/$H$42 -> #DIV/0! | Z40: 40. ¿Su negocio promueve la igualdad en la remuneración?
B41: Cooperativa: Propiedad colectiva de miembros que comparten beneficios y decisiones. | H41: =COUNTIF('M&E_ESP_FINAL'!$I$6:$I60,"*Cooperativa*") -> 0 | I41: =H41/$H$42 -> #DIV/0! | N41: 18. ¿Cuenta con un proceso de selección de personal que asegure la inclusión y la no discriminación? | AA41: INICIO | AC41: FINAL
H42: =SUM(H37:H41) -> 0 | O42: INICIO | Q42: FINAL | Z42: Sí, cuenta con políticas | AA42: =COUNTIF('M&E_ESP_FINAL'!$CD$6:$CD60,"*Sí, cuenta con políticas*") -> 0 | AB42: =AA42/$AA$46 -> #DIV/0! | AC42: =COUNTIF('M&E_ESP_FINAL'!$CE$6:$CE60,"*Sí, cuenta con políticas*") -> 0 | AD42: =AC42/$AC$46 -> #DIV/0!
N43: Sí | O43: =COUNTIF('M&E_ESP_FINAL'!$AL$6:$AL60,"*Sí*") -> 0 | P43: =$O$43/$O$45 -> #DIV/0! | Q43: =COUNTIF('M&E_ESP_FINAL'!$AM$6:$AM59,"*Sí*") -> 0 | R43: =$Q$43/$Q$45 -> #DIV/0! | Z43: Sí, de manera informal | AA43: =COUNTIF('M&E_ESP_FINAL'!$CD$6:$CD60,"*Sí, de manera informal*") -> 0 | AB43: =AA43/$AA$46 -> #DIV/0! | AC43: =COUNTIF('M&E_ESP_FINAL'!$CE$6:$CE60,"*Sí, de manera informal*") -> 0 | AD43: =AC43/$AC$46 -> #DIV/0!
...

Sheet M&E_ESP_RSPTAs
B2: Herramienta de Monitoreo y Evaluación Cadenas de Valor Inclusivas | E2: El decisor(a) del negocio es aquella persona responsible de la toma de decisión final de la organización. Algunas veces es el dueño(a) del negocio, otras veces el Gerente General, etc. | G2: Omitir pregunta en caso se aplique en SDP | W2: Omitir en caso la respuesta anterior sea no | AH2: Las discapacidades pueden ser clasificadas en físicas, visual/auditiva, intelectual, psicosocial, múltiple. Esta pregunta no necesita especificación del tipo de discapacidad. | AJ2: Una persona en situación de vulnerabilidad es aquella que sufre múltiples desventajas estructurales (económicas, sociales, de salud, de género, étnicas, territoriales, etc) | AP2: Puede especificarse en moneda local | AQ2: Puede especificarse en moneda local | AR2: Es importante que si no se cuenta con este dato, debe apoyarse a calcularlo y agregarlo. El margen de utilidad bruta es un indicador financiero que muestra qué tan rentable es la negocio antes de considerar gastos operativos, impuestos y otros costos indirectos. Se calcula a partir de las ventas y el costo directo de producir los bienes o servicios. | AT2: El total de horas trabajadas es la sumatoria total de todas las horas trabajadas por todos los(as) empleados del negocio en un determinado periodo | AV2: Esta pregunta es importante porque nos permite conocer el volumen de productos fabricados o servicios entregados por su negocio. Con esta información podemos calcular indicadores clave como la productividad y la innovación en productos, que son fundamentales para evaluar el desempeño y el crecimiento del negocio. | BB2: Incluya únicamente negocios u organizaciones registradas fiscalmente que compran directamente sus productos o servicios, no distribuidores ni consumidores finales. | CJ2: Con software nos referimos a cualquier programa o sistema operativo que apoye al negocio en la gestión de sus operaciones. Desde MS Microsoft hasta softwares de gestión (SAP, Oracle)
B3: Implementación | D3: Información General del decisor (a) del negocio | H3: Información General del Negocio | Z3: Generación de empleo | AN3: Operaciones y ventas | BN3: Gestión Financiera | BX3: Cultura organizacional | CH3: Digitalización | CN3: Gestión del Riesgo de desastres | CT3: Gestión ambiental
R4: FINAL | T4: FINAL | V4: FINAL | X4: FINAL | AA4: FINAL | AC4: FINAL | AE4: FINAL | AG4: FINAL | AI4: FINAL | AK4: FINAL | AM4: FINAL | AO4: FINAL | AQ4: FINAL | AS4: FINAL | AU4: FINAL | AW4: FINAL | AY4: FINAL | BA4: FINAL | BC4: FINAL | BE4: FINAL | BG4: FINAL | BI4: FINAL | BK4: FINAL | BM4: FINAL | BO4: FINAL | BQ4: FINAL | BS4: FINAL | BU4: FINAL | BW4: FINAL | BY4: FINAL | CA4: FINAL | CC4: FINAL | CE4: FINAL | CG4: FINAL | CI4: FINAL | CK4: FINAL | CM4: FINAL | CO4: FINAL | CQ4: FINAL | CS4: FINAL | CU4: FINAL | CW4: FINAL
B5: País | C5: Metodología aplicada | D5: Género | E5: Edad | F5: Nivel educativo | G5: ¿Es el negocio su principal fuente de ingresos? | H5: Nombre comercial del negocio | I5: Tipo de propiedad de su negocio | J5: Municipio | K5: Región | L5: Describir la actividad económica específica del negocio | M5: CIIU un dígito | N5: CIIU a dos dígitos | O5: CIIU a tres dígitos | P5: Años en operación (periodo de tiempo en el que el negocio opera activamente y puede ser distinto a años desde la fundación) | Q5: ¿Su negocio cuenta con registro legal activo? | R5: ¿Su negocio cuenta con registro legal activo? | S5: ¿Su negocio cumple con las obligaciones tributarias correspondientes? | T5: ¿Su negocio cumple con las obligaciones tributarias correspondientes? | U5: ¿Su negocio participa en redes, plataformas o espacios que fomenten alianzas estratégicas y colaboración con otras organizaciones? | V5: ¿Su negocio participa en redes, plataformas o espacios que fomenten alianzas estratégicas y colaboración con otras organizaciones? | W5: Si la respuesta es sí, especifique cuáles. Opción múltiple | X5: Si la respuesta es sí, especifique cuáles. Opción múltiple | Y5: ¿Usted o alguien de su equipo ha recibido capacitación formal relacionada con la gestión y operación del negocio? (Por ejemplo: cursos, talleres, diplomados en administración, finanzas, marketing, etc.) | Z5: ¿Cuántas personas en total trabajan actualmente en su negocio? Si es un negocio unipersonal, incluir a la persona dueña. También incluir personal temporal y fijo. | AA5: ¿Cuántas personas en total trabajan actualmente en su negocio? Si es un negocio unipersonal, incluir a la persona dueña. También incluir personal temporal y fijo. | AB5: ¿A cuántas mujeres emplea actualmente su negocio? No incluir a la persona dueña. Sí incluya personal temporal y fijo. | AC5: ¿A cuántas mujeres emplea actualmente su negocio? No incluir a la persona dueña. Sí incluya personal temporal y fijo. | AD5: ¿A cuántos hombres emplea actualmente su negocio? No incluir a la persona dueña. Sí incluya personal temporal y fijo. | AE5: ¿A cuántos hombres emplea actualmente su negocio? No incluir a la persona dueña. Sí incluya personal temporal y fijo. | AF5: ¿A cuántos jóvenes (mujeres y hombres) emplea actualmente su negocio? No incluir a la persona dueña. Sí incluya personal temporal y fijo. Una persona joven se considera entre los 18 a los 29 años. | AG5: ¿A cuántos jóvenes (mujeres y hombres) emplea actualmente su negocio? No incluir a la persona dueña. Sí incluya personal temporal y fijo. Una persona joven se considera entre los 18 a los 29 años. | AH5: ¿Cuántas personas con alguna discapacidad emplea actualmente su negocio? No incluir a la persona dueña. Sí incluya personal temporal y fijo. | AI5: ¿Cuántas personas con alguna discapacidad emplea actualmente su negocio? No incluir a la persona dueña. Sí incluya personal temporal y fijo. | AJ5: ¿Cuántas personas en situación de vulnerabilidad emplea actualmente su negocio? No incluir a la persona dueña. Sí incluya personal temporal y fijo. | AK5: ¿Cuántas personas en situación de vulnerabilidad emplea actualmente su negocio? No incluir a la persona dueña. Sí incluya personal temporal y fijo. | AL5: ¿Cuenta con un proceso de selección de personal que asegure la inclusión y la no discriminación? | AM5: ¿Cuenta con un proceso de selección de personal que asegure la inclusión y la no discriminación? | AN5: ¿Su negocio lleva un registro ordenado y constante de sus ventas y costos? (Esto incluye anotar todas las ventas y los costos asociados de manera regular, para poder calcular indicadores como el margen bruto). | AO5: ¿Su negocio lleva un registro ordenado y constante de sus ventas y costos? (Esto incluye anotar todas las ventas y los costos asociados de manera regular, para poder calcular indicadores como el margen bruto). | AP5: ¿Cuál es el promedio mensual de ventas de su negocio en CUP? (Si su negocio es estacional, calcule el promedio dividiendo el total de ventas del último año calendario entre 12 meses). | AQ5: ¿Cuál es el promedio mensual de ventas de su negocio en CUP? (Si su negocio es estacional, calcule el promedio dividiendo el total de ventas del último año calendario entre 12 meses). | AR5: ¿Cuál es el margen (%) de utilidad bruta de su negocio? | AS5: ¿Cuál es el margen (%) de utilidad bruta de su negocio? | AT5: ¿Cuál es el total de horas trabajadas en un mes aproximadamente? | AU5: ¿Cuál es el total de horas trabajadas en un mes aproximadamente? | AV5: ¿Cuántos productos fabrica o cuántos servicios entrega su negocio en promedio al mes? (Indique un número aproximado considerando la producción o prestación habitual. Si su negocio es estacional, calcule el promedio mensual tomando el total anual y dividiéndolo entre 12). | AW5: ¿Cuántos productos fabrica o cuántos servicios entrega su negocio en promedio al mes? (Indique un número aproximado considerando la producción o prestación habitual. Si su negocio es estacional, calcule el promedio mensual tomando el total anual y dividiéndolo entre 12). | AX5: En los últimos 3 meses, ¿su negocio ha introducido nuevos productos o servicios, o ha innovado en los existentes (por ejemplo, mejoras en diseño, funcionalidad o procesos)? | AY5: En los últimos 3 meses, ¿su negocio ha introducido nuevos productos o servicios, o ha innovado en los existentes (por ejemplo, mejoras en diseño, funcionalidad o procesos)? | AZ5: ¿En promedio, cuántos clientes finales (personas) atiende su negocio al mes? (Si su negocio es estacional, calcule el promedio mensual tomando el total de clientes atendidos en el último año y divídalo entre 12). | BA5: ¿En promedio, cuántos clientes finales (personas) atiende su negocio al mes? (Si su negocio es estacional, calcule el promedio mensual tomando el total de clientes atendidos en el último año y divídalo entre 12). | BB5: ¿En promedio, cuántos clientes comerciales (negocios u otras entidades registradas fiscalmente) atiende su negocio al mes? (Si su negocio es estacional, calcule el promedio mensual tomando el total de clientes comerciales atendidos en el último año y divídalo entre 12). | BC5: ¿En promedio, cuántos clientes comerciales (negocios u otras entidades registradas fiscalmente) atiende su negocio al mes? (Si su negocio es estacional, calcule el promedio mensual tomando el total de clientes comerciales atendidos en el último año y divídalo entre 12). | BD5: ¿Cuántos canales de venta tiene el negocio? Colocar el número | BE5: ¿Cuántos canales de venta tiene el negocio? | BF5: ¿Cuáles son los principales canales de venta de su negocio? | BG5: ¿Cuáles son los principales canales de venta de su negocio? Selección múltiple | BH5: ¿Qué tan competitiva considera que es su negocio? | BI5: ¿Qué tan competitiva considera que es su negocio? | BJ5: ¿Su negocio segmenta el mercado por criterios demográficos, psicográficos o de género? | BK5: ¿Su negocio segmenta el mercado por criterios demográficos, psicográficos o de género? | BL5: ¿Su negocio dispone de elementos de imagen comercial, como logotipo, colores corporativos y diseño consistente en sus materiales? | BM5: ¿Su negocio dispone de elementos de imagen comercial, como logotipo, colores corporativos y diseño consistente en sus materiales? | BN5: ¿Cómo describiría el nivel de gestión financiera? | BO5: ¿Cómo describiría el nivel de gestión financiera? | BP5: ¿El negocio separa satisfactoriamente las finanzas personales de las finanzas del negocio? | BQ5: ¿El negocio separa satisfactoriamente las finanzas personales de las finanzas del negocio? | BR5: ¿Ha recibido capacitación en educación financiera en los últimos 12 meses? | BS5: ¿Ha recibido capacitación en educación financiera en los últimos 12 meses? | BT5: ¿Su negocio utiliza una cuenta bancaria propia para sus operaciones? | BU5: ¿Su negocio utiliza una cuenta bancaria propia para sus operaciones? | BV5: ¿Qué tipo(s) de financiamiento externo ha utilizado su negocio en los últimos 24 meses? (Seleccione todas las que correspondan) | BW5: ¿Qué tipo(s) de financiamiento externo ha utilizado su negocio en los últimos 24 meses? (Seleccione todas las que correspondan) | BX5: ¿Su negocio cuenta con prácticas y/o políticas que prohíben expresamente la violencia basada en género (VBG)? | BY5: ¿Su negocio cuenta con prácticas y/o políticas que prohíben expresamente la violencia basada en género (VBG)? | BZ5: ¿Su negocio ha definido explícitamente su modelo de negocio (por ejemplo, propuesta de valor, segmentos de clientes, canales, fuentes de ingresos, costos, etc.)? | CA5: ¿Su negocio ha definido explícitamente su modelo de negocio (por ejemplo, propuesta de valor, segmentos de clientes, canales, fuentes de ingresos, costos, etc.)? | CB5: ¿Su negocio establece objetivos y estrategias anuales/procesos de planificación estratégica para orientar sus actividades? | CC5: ¿Su negocio establece objetivos y estrategias anuales/procesos de planificación estratégica para orientar sus actividades? | CD5: ¿Su negocio promueve la igualdad en la remuneración? | CE5: ¿Su negocio promueve la igualdad en la remuneración? | CF5: ¿Qué nivel de participación tienen las mujeres de su negocio en espacios de toma de decisión? | CG5: ¿Qué nivel de participación tienen las mujeres de su negocio en espacios de toma de decisión? | CH5: ¿Qué presencia digital tiene su negocio (sitio web, redes sociales, e-commerce)? Seleccione principales plataformas. | CI5: ¿Qué presencia digital tiene su negocio (sitio web, redes sociales, e-commerce)? Seleccione principales plataformas. | CJ5: ¿Utiliza algún software para la operación del negocio? | CK5: ¿Utiliza algún software para la operación del negocio? | CL5: ¿Con qué frecuencia utiliza el negocio medios de pagos digitales? | CM5: ¿Con qué frecuencia utiliza el negocio medios de pagos digitales? | CN5: ¿El negocio ha identificado los principales riesgos que enfrenta? | CO5: ¿El negocio ha identificado los principales riesgos que enfrenta? | CP5: ¿Qué porcentaje de empleados está capacitado en gestión del riesgo de desastres? | CQ5: ¿Qué porcentaje de empleados está capacitado en gestión del riesgo de desastres? | CR5: ¿Existe un plan de continuidad de negocio documentado y actualizado? | CS5: ¿Existe un plan de continuidad de negocio documentado y actualizado? | CT5: ¿Su negocio cuenta con prácticas para la gestión adecuada de residuos sólidos generados por sus operaciones? (Por ejemplo: separación, reciclaje, disposición segura, recolección por gestores autorizados). | CU5: ¿Su negocio cuenta con prácticas para la gestión adecuada de residuos sólidos generados por sus operaciones? (Por ejemplo: separación, reciclaje, disposición segura, recolección por gestores autorizados). | CV5: ¿Mantiene un control del consumo de agua y energía de su negocio? | CW5: ¿Mantiene un control del consumo de agua y energía de su negocio?
A6: Respuestas | B6: LATAM | C6: CCSN | D6: Mujer | F6: Básica | G6: Sí | I6: MIPYME: sociedad de responsabilidad limitada unipersonal | M6: Opciones CIIU a un dígito | N6: Opciones CIIU a dos dígitos | O6: Opciones CIIU a tres dígitos | Q6: Sí | R6: Sí | S6: Sí | T6: Sí | U6: Sí | V6: Sí | W6: Cámaras de comercio locales, nacionales o internacionales | X6: Cámaras de comercio locales, nacionales o internacionales | Y6: Sí, hemos recibido capacitación formal en gestión y operación del negocio. | AL6: Sí | AM6: Sí | AN6: Sí | AO6: Sí | AX6: Sí | AY6: Sí | AZ6: Menos de 10 | BA6: Menos de 10 | BB6: Menos de 10 | BC6: Menos de 10 | BF6: Tienda física | BG6: Tienda física | BH6: Muy baja: Nuestro negocio tiene dificultades para competir en su sector. | BI6: Muy baja: Nuestro negocio tiene dificultades para competir en su sector. | BJ6: Sí, utilizamos criterios demográficos, psicográficos y de género. | BK6: Sí, utilizamos criterios demográficos, psicográficos y de género. | BL6: No, el negocio no cuenta con elementos de imagen comercial. | BM6: No, el negocio no cuenta con elementos de imagen comercial. | BN6: Inexistentes: No lleva registro de ventas y gastos, no hay control de flujo de caja, no se utiliza ningún software ni hojas de cálculo, las decisiones financieras se toman de manera reactiva. | BO6: Inexistentes: No lleva registro de ventas y gastos, no hay control de flujo de caja, no se utiliza ningún software ni hojas de cálculo, las decisiones financieras se toman de manera reactiva. | BP6: No, las finanzas personales y del negocio no se separan. | BQ6: No, las finanzas personales y del negocio no se separan. | BR6: Sí | BS6: Sí | BT6: Sí, cuenta con una cuenta bancaria negociorial a nombre del negocio. | BU6: Sí, cuenta con una cuenta bancaria negociorial a nombre del negocio. | BV6: Préstamos informales: créditos obtenidos fuera del sistema financiero formal como por ejemplo, prestamistas, amigos, conocidos. | BW6: Préstamos informales: créditos obtenidos fuera del sistema financiero formal como por ejemplo, prestamistas, amigos, conocidos. | BX6: No existen políticas ni prácticas sobre VBG. | BY6: No existen políticas ni prácticas sobre VBG. | BZ6: No tenemos un modelo de negocio definido. | CA6: No tenemos un modelo de negocio definido. | CB6: Sí, contamos con un plan estratégico formal y documentado. | CC6: Sí, contamos con un plan estratégico formal y documentado. | CD6: Sí, cuenta con políticas claras y aplicadas | CE6: Sí, cuenta con políticas claras y aplicadas | CF6: Nula: No hay mujeres en espacios de decisión. | CG6: Nula: No hay mujeres en espacios de decisión. | CH6: Ninguna: No tiene presencia digital. | CI6: Ninguna: No tiene presencia digital. | CJ6: No utilizamos ningún software para gestionar el negocio. | CK6: No utilizamos ningún software para gestionar el negocio. | CL6: No utilizamos ningún medio de pago digital. | CM6: No utilizamos ningún medio de pago digital. | CN6: Sí | CO6: Sí | CP6: 0%: Ningún empleado capacitado. | CQ6: 0%: Ningún empleado capacitado. | CR6: No contamos con un plan de continuidad del negocio. | CS6: No contamos con un plan de continuidad del negocio. | CT6: Sí, contamos con un sistema formal de gestión de residuos sólidos (separación, reciclaje y disposición segura). | CU6: Sí, contamos con un sistema formal de gestión de residuos sólidos (separación, reciclaje y disposición segura). | CV6: Sí, mantenemos control del consumo de agua y energía. | CW6: Sí, mantenemos control del consumo de agua y energía.
C7: ICSN | D7: Hombre | F7: Ténica | G7: No | I7: MIPYME: sociedad de responsabilidad limitada pluripersonal | Q7: No | R7: No | S7: No | T7: No | U7: No | V7: No | W7: Redes negocioriales sectoriales | X7: Redes negocioriales sectoriales | Y7: Estamos en proceso de recibir capacitación (inscritos o participando actualmente en un curso). | AL7: No | AM7: No | AN7: No | AO7: No | AX7: No | AY7: No | AZ7: 11 a 20 | BA7: 11 a 20 | BB7: 11 a 20 | BC7: 11 a 20 | BF7: Página web propia | BG7: Página web propia | BH7: Baja: Estamos por debajo del promedio del sector. | BI7: Baja: Estamos por debajo del promedio del sector. | BJ7: Sí, utilizamos algunos de estos criterios (por ejemplo, solo demográficos o género). | BK7: Sí, utilizamos algunos de estos criterios (por ejemplo, solo demográficos o género). | BL7: Sí, contamos con algunos elementos básicos (por ejemplo, solo logotipo). | BM7: Sí, contamos con algunos elementos básicos (por ejemplo, solo logotipo). | BN7: Básicos: Se anotan ingresos y gastos en cuadernos o registros manuales, se revisa el flujo de caja solo cuando hay problemas de liquidez, no hay presupuestos formales, no se usan software, sólo cálculos manuales. | BO7: Básicos: Se anotan ingresos y gastos en cuadernos o registros manuales, se revisa el flujo de caja solo cuando hay problemas de liquidez, no hay presupuestos formales, no se usan software, sólo cálculos manuales. | BP7: Parcialmente, se separan en la mayoría de los casos, aunque hay ocasiones en que se mezclan. | BQ7: Parcialmente, se separan en la mayoría de los casos, aunque hay ocasiones en que se mezclan. | BR7: No | BS7: No | BT7: No tiene cuenta negociorial, pero utiliza la cuenta bancaria personal del propietario para las operaciones del negocio. | BU7: No tiene cuenta negociorial, pero utiliza la cuenta bancaria personal del propietario para las operaciones del negocio. | BV7: Fondos familiares: Recursos económicos aportados por familiares para financiar el negocio. | BW7: Fondos familiares: Recursos económicos aportados por familiares para financiar el negocio. | BX7: Hay prácticas informales que desalientan la VBG, pero no son sistemáticas. | BY7: Hay prácticas informales que desalientan la VBG, pero no son sistemáticas. | BZ7: Conocemos algunos elementos (por ejemplo, clientes o propuesta de valor), pero no está estructurado. | CA7: Conocemos algunos elementos (por ejemplo, clientes o propuesta de valor), pero no está estructurado. | CB7: Sí, definimos objetivos anuales, pero no contamos con un plan estratégico formal. | CC7: Sí, definimos objetivos anuales, pero no contamos con un plan estratégico formal. | CD7: Sí, de manera informal (sin políticas escritas) | CE7: Sí, de manera informal (sin políticas escritas) | CF7: Baja: Participan ocasionalmente, sin roles de liderazgo. | CG7: Baja: Participan ocasionalmente, sin roles de liderazgo. | CH7: Solo redes sociales: Facebook, Instagram, TikTok. | CI7: Solo redes sociales: Facebook, Instagram, TikTok. | CJ7: Utilizamos herramientas básicas de oficina (ej. Microsoft Excel, Word). | CK7: Utilizamos herramientas básicas de oficina (ej. Microsoft Excel, Word). | CL7: Utilizamos pagos digitales solamente para recibir pagos. | CM7: Utilizamos pagos digitales solamente para recibir pagos. | CN7: No | CO7: No | CP7: 1% - 25%: Muy pocos empleados capacitados. | CQ7: 1% - 25%: Muy pocos empleados capacitados. | CR7: Contamos con acciones informales para emergencias, pero no con un plan de continuidad del negocio formal. | CS7: Contamos con acciones informales para emergencias, pero no con un plan de continuidad del negocio formal. | CT7: Sí, realizamos algunas prácticas básicas (por ejemplo, separación parcial o entrega a recolectores informales). | CU7: Sí, realizamos algunas prácticas básicas (por ejemplo, separación parcial o entrega a recolectores informales). | CV7: Sí, mantenemos control solo del consumo de agua. | CW7: Sí, mantenemos control solo del consumo de agua.
C8: MDP | D8: No Binaria | F8: Universidad | I8: Proyecto de Desarrollo Local | S8: Parcialmente | T8: Parcialmente | W8: Redes de sostenibilidad y RSE | X8: Redes de sostenibilidad y RSE | Y8: No, no hemos recibido capacitación formal en gestión y operación del negocio. | AZ8: 21 a 50 | BA8: 21 a 50 | BB8: 21 a 50 | BC8: 21 a 50 | BF8: Redes sociales | BG8: Redes sociales | BH8: Media: Somos competitivos en algunos aspectos, pero aún con varias brechas. | BI8: Media: Somos competitivos en algunos aspectos, pero aún con varias brechas. | BJ8: No, no segmentamos el mercado con estos criterios. | BK8: No, no segmentamos el mercado con estos criterios. | BL8: Sí, contamos con varios elementos de imagen comercial, pero no se usan de forma consistente. | BM8: Sí, contamos con varios elementos de imagen comercial, pero no se usan de forma consistente. | BN8: Intermedios: Se lleva el control de costos en hojas de cálculo, se proyecta el fliujo de caja mensual, se tiene un presupuesto annual básico, se utiliza un software contable simple (para facturación) | BO8: Intermedios: Se lleva el control de costos en hojas de cálculo, se proyecta el fliujo de caja mensual, se tiene un presupuesto annual básico, se utiliza un software contable simple (para facturación) | BP8: Sí, están totalmente separadas y existen mecanismos formales (cuentas separadas, registros contables, controles). | BQ8: Sí, están totalmente separadas y existen mecanismos formales (cuentas separadas, registros contables, controles). | BT8: No utiliza ninguna cuenta bancaria para las operaciones del negocio. | BU8: No utiliza ninguna cuenta bancaria para las operaciones del negocio. | BV8: Préstamo bancario | BW8: Préstamo bancario | BX8: Existe al menos un documento o procedimiento, pero su implementación es parcial. | BY8: Existe al menos un documento o procedimiento, pero su implementación es parcial. | BZ8: Contamos con la mayoría de los elementos definidos, aunque sin documentación formal. | CA8: Contamos con la mayoría de los elementos definidos, aunque sin documentación formal. | CB8: Estamos en proceso de desarrollar objetivos y/o un plan estratégico. | CC8: Estamos en proceso de desarrollar objetivos y/o un plan estratégico. | CD8: No, pero está en proceso de implementarlas | CE8: No, pero está en proceso de implementarlas | CF8: Media: Participan regularmente, algunos roles de liderazgo. | CG8: Media: Participan regularmente, algunos roles de liderazgo. | CH8: Redes sociales + sitio web. | CI8: Redes sociales + sitio web. | CJ8: Utilizamos software especializado para tareas específicas (ej. facturación, inventario, contabilidad). | CK8: Utilizamos software especializado para tareas específicas (ej. facturación, inventario, contabilidad). | CL8: Utilizamos pagos digitales solamente para hacer pagos. | CM8: Utilizamos pagos digitales solamente para hacer pagos. | CP8: 26% - 50% : Aproximadamente la mitad del personal capacitado. | CQ8: 26% - 50% : Aproximadamente la mitad del personal capacitado. | CR8: Contamos con un plan de continuidad del negocio, pero necesita actualización. | CS8: Contamos con un plan de continuidad del negocio, pero necesita actualización. | CT8: No, no contamos con prácticas específicas para la gestión de residuos sólidos. | CU8: No, no contamos con prácticas específicas para la gestión de residuos sólidos. | CV8: Sí, mantenemos control solo del consumo de energía. | CW8: Sí, mantenemos control solo del consumo de energía.
C9: En Marcha | D9: Prefiero no especificar | F9: Posgrado | I9: Trabajador por Cuenta Propia | S9: No lo sé | T9: No lo sé | W9: Incubadoras y aceleradoras | X9: Incubadoras y aceleradoras | AZ9: Más de 50 | BA9: Más de 50 | BB9: Más de 50 | BC9: Más de 50 | BF9: Distribuidores / Mayoristas | BG9: Distribuidores / Mayoristas | BH9: Alta: Competimos bien y en muchos aspectos estamos por encima del promedio. | BI9: Alta: Competimos bien y en muchos aspectos estamos por encima del promedio. | BJ9: No aplica (nuestros productos/servicios no requieren segmentación). | BK9: No aplica (nuestros productos/servicios no requieren segmentación). | BL9: Sí, contamos con una identidad visual completa (logotipo, colores, tipografías, lineamientos) y se aplica de manera consistente. | BM9: Sí, contamos con una identidad visual completa (logotipo, colores, tipografías, lineamientos) y se aplica de manera consistente. | BN9: Avanzados: Procesos estandarizados para control de costos y análisis de rentabilidad, flujo de caja proyectado trimestralmente, uso de software contable especializado (Quickbooks, Contpaq, etc) Informes financieros periódicos para la toma de decisiones. | BO9: Avanzados: Procesos estandarizados para control de costos y análisis de rentabilidad, flujo de caja proyectado trimestralmente, uso de software contable especializado (Quickbooks, Contpaq, etc) Informes financieros periódicos para la toma de decisiones. | BV9: Inversión privada | BW9: Inversión privada | BX9: La política está implementada y es conocida por el personal. | BY9: La política está implementada y es conocida por el personal. | BZ9: Tenemos un modelo de negocio completo y documentado (Ejemplo: Modelo de Negocio Canva) | CA9: Tenemos un modelo de negocio completo y documentado (Ejemplo: Modelo de Negocio Canva) | CB9: No realizamos planificación estratégica ni establecemos objetivos anuales. | CC9: No realizamos planificación estratégica ni establecemos objetivos anuales. | CD9: No | CE9: No | CF9: Alta: Participan activamente y ocupan cargos relevantes. | CG9: Alta: Participan activamente y ocupan cargos relevantes. | CH9: Redes sociales + sitio web + e-commerce. | CI9: Redes sociales + sitio web + e-commerce. | CJ9: Utilizamos un sistema integrado de gestión para varias áreas (ej. QuickBooks. | CK9: Utilizamos un sistema integrado de gestión para varias áreas (ej. QuickBooks. | CL9: Utilizamos pagos digitales tanto para cobrar como para pagar, pero no regularmente. | CM9: Utilizamos pagos digitales tanto para cobrar como para pagar, pero no regularmente. | CP9: 51% - 75%: Mayoría del personal capacitado. | CQ9: 51% - 75%: Mayoría del personal capacitado. | CR9: Contamos con un plan de continuidad del negocio actualizado que se revisa y comunica al personal. | CS9: Contamos con un plan de continuidad del negocio actualizado que se revisa y comunica al personal. | CT9: No aplica (nuestro negocio no genera residuos sólidos significativos). | CU9: No aplica (nuestro negocio no genera residuos sólidos significativos). | CV9: No, no mantenemos control del consumo de agua ni de energía. | CW9: No, no mantenemos control del consumo de agua ni de energía.
C10: En Marcha Digital | F10: Sin instrucción formal | I10: Cooperativa no Agropecuaria | W10: Comunidades digitales de negocios (LinkedIn Groups, plataformas B2B) | X10: Comunidades digitales de negocios (LinkedIn Groups, plataformas B2B) | BF10: Marketplaces (ej. Amazon, Mercado Libre) | BG10: Marketplaces (ej. Amazon, Mercado Libre) | BH10: Muy alta: Somos líderes o referentes en nuestro mercado. | BI10: Muy alta: Somos líderes o referentes en nuestro mercado. | BL10: Sí, contamos con una identidad visual completa y además con un manual de marca formalmente establecido. | BM10: Sí, contamos con una identidad visual completa y además con un manual de marca formalmente establecido. | BV10: Remesas familiares | BW10: Remesas familiares | BX10: La política está implementada, el personal está capacitado y existe un mecanismo para reportes. | BY10: La política está implementada, el personal está capacitado y existe un mecanismo para reportes. | BZ10: El modelo de negocio está documentado, se revisa periódicamente y guía decisiones estratégicas. | CA10: El modelo de negocio está documentado, se revisa periódicamente y guía decisiones estratégicas. | CF10: Muy alta :Lideran espacios y tienen influencia significativa. | CG10: Muy alta :Lideran espacios y tienen influencia significativa. | CH10: Ecosistema digital completo (integración con CRM, publicidad digital, analítica). | CI10: Ecosistema digital completo (integración con CRM, publicidad digital, analítica). | CJ10: Utilizamos un ERP empresarial avanzado (ej. SAP, Oracle, Microsoft Dynamics). | CK10: Utilizamos un ERP empresarial avanzado (ej. SAP, Oracle, Microsoft Dynamics). | CL10: Utilizamos pagos digitales de manera habitual para la mayoría de transacciones. | CM10: Utilizamos pagos digitales de manera habitual para la mayoría de transacciones. | CP10: 76% - 100% :Todo o casi todo el personal capacitado. | CQ10: 76% - 100% :Todo o casi todo el personal capacitado.
F11: Prefiere no especificar | BF11: Fuerza de ventas/ ventas directas (equipo comercial) | BG11: Fuerza de ventas/ ventas directas (equipo comercial) | BV11: Donaciones | BW11: Donaciones
BF12: Otros | BG12: Otros | BV12: No he recibido ningún tipo de financiamiento externo | BW12: No he recibido ningún tipo de financiamiento externo

Sheet CIIU
B2: Uso del CIIU en el Sistema Integrado de Monitoreo Empresarial
B4: El CIIU (Clasificación Industrial Internacional Uniforme de todas las actividades económicas, Revisión 4 adaptada para América Latina – CIIU Rev.4 A.C.) permite identificar y categorizar la actividad económica principal de cada empresa.
C6: Campo | D6: Nivel de detalle | E6: Uso en la ficha | F6: Ejemplo
C7: CIIU a 1 dígito | D7: Sección – identifica el gran sector económico | E7: Define el macrosector de la empresa. | F7: A - AGRICULTURA, GANADERÍA, SILVICULTURA Y PESCA.
C8: CIIU a 2 dígitos | D8: División – describe la rama principal de actividad | E8: Permite agrupar por cadena productiva o tipo de industria. | F8: A01 - AGRICULTURA, GANADERÍA, CAZA Y ACTIVIDADES DE SERVICIOS CONEXAS.
C9: CIIU a 3 dígitos | D9: Grupo – especifica el tipo exacto de producción o servicio | E9: Permite análisis más precisos dentro del sector. | F9: A014 - GANADERÍA.
B11: CODIGO | C11: DESCRIPCION | F11: NIVEL
B12: A | C12: AGRICULTURA, GANADERÍA, SILVICULTURA Y PESCA. | F12: 1
B13: A01 | C13: AGRICULTURA, GANADERÍA, CAZA Y ACTIVIDADES DE SERVICIOS CONEXAS. | F13: 2
B14: A011 | C14: CULTIVO DE PLANTAS NO PERENNES. | F14: 3
B15: A012 | C15: CULTIVO DE PLANTAS PERENNES. | F15: 3
B16: A013 | C16: PROPAGACIÓN DE PLANTAS. | F16: 3
B17: A014 | C17: GANADERÍA. | F17: 3
B18: A015 | C18: CULTIVO DE PRODUCTOS AGRÍCOLAS EN COMBINACIÓN CON LA CRÍA DE ANIMALES (EXPLOTACIÓN MIXTA). | F18: 3
B19: A016 | C19: ACTIVIDADES DE APOYO A LA AGRICULTURA Y LA GANADERÍA Y ACTIVIDADES POSCOSECHA. | F19: 3
B20: A017 | C20: CAZA ORDINARIA, MEDIANTE TRAMPAS Y ACTIVIDADES DE SERVICIOS CONEXAS. | F20: 3
B21: A02 | C21: SILVICULTURA Y EXTRACCIÓN DE MADERA. | F21: 2
B22: A021 | C22: SILVICULTURA Y OTRAS ACTIVIDADES FORESTALES. | F22: 3
B23: A022 | C23: EXTRACCIÓN DE MADERA. | F23: 3
